<?xml version="1.0" encoding="UTF-8"?>
<!-- Generated by org.testng.reporters.JUnitXMLReporter -->
<testsuite hostname="DESKTOP-OKDV62E" ignored="0" name="Default test" tests="3" failures="3" timestamp="2020-05-21T10:13:24 EDT" time="256.9" errors="0">
  <testcase name="testMethod" time="92.424" classname="testng.testingonly">
    <failure type="org.apache.poi.openxml4j.exceptions.OpenXML4JRuntimeException" message="Fail to save: an error occurs while saving the package : null">
      <![CDATA[org.apache.poi.openxml4j.exceptions.OpenXML4JRuntimeException: Fail to save: an error occurs while saving the package : null
at org.apache.poi.openxml4j.opc.ZipPackage.saveImpl(ZipPackage.java:602)
at org.apache.poi.openxml4j.opc.OPCPackage.save(OPCPackage.java:1557)
at org.apache.poi.POIXMLDocument.write(POIXMLDocument.java:248)
at configuration.excel.writeCellData(excel.java:174)
at testng.testingonly.writeToExcel(testingonly.java:1042)
at testng.testingonly.getRerateId(testingonly.java:1033)
at testng.testingonly.thirdPage(testingonly.java:928)
at testng.testingonly.doWork(testingonly.java:404)
at testng.testingonly.testMethod(testingonly.java:279)
at sun.reflect.NativeMethodAccessorImpl.invoke0(Native Method)
at sun.reflect.NativeMethodAccessorImpl.invoke(Unknown Source)
at sun.reflect.DelegatingMethodAccessorImpl.invoke(Unknown Source)
at java.lang.reflect.Method.invoke(Unknown Source)
at org.testng.internal.MethodInvocationHelper.invokeMethod(MethodInvocationHelper.java:133)
at org.testng.internal.TestInvoker.invokeMethod(TestInvoker.java:584)
at org.testng.internal.TestInvoker.invokeTestMethod(TestInvoker.java:172)
at org.testng.internal.MethodRunner.runInSequence(MethodRunner.java:46)
at org.testng.internal.TestInvoker$MethodInvocationAgent.invoke(TestInvoker.java:804)
at org.testng.internal.TestInvoker.invokeTestMethods(TestInvoker.java:145)
at org.testng.internal.TestMethodWorker.invokeTestMethods(TestMethodWorker.java:146)
at org.testng.internal.TestMethodWorker.run(TestMethodWorker.java:128)
at java.util.ArrayList.forEach(Unknown Source)
at org.testng.TestRunner.privateRun(TestRunner.java:770)
at org.testng.TestRunner.run(TestRunner.java:591)
at org.testng.SuiteRunner.runTest(SuiteRunner.java:402)
at org.testng.SuiteRunner.runSequentially(SuiteRunner.java:396)
at org.testng.SuiteRunner.privateRun(SuiteRunner.java:355)
at org.testng.SuiteRunner.run(SuiteRunner.java:304)
at org.testng.SuiteRunnerWorker.runSuite(SuiteRunnerWorker.java:53)
at org.testng.SuiteRunnerWorker.run(SuiteRunnerWorker.java:96)
at org.testng.TestNG.runSuitesSequentially(TestNG.java:1180)
at org.testng.TestNG.runSuitesLocally(TestNG.java:1102)
at org.testng.TestNG.runSuites(TestNG.java:1032)
at org.testng.TestNG.run(TestNG.java:1000)
at org.testng.remote.AbstractRemoteTestNG.run(AbstractRemoteTestNG.java:115)
at org.testng.remote.RemoteTestNG.initAndRun(RemoteTestNG.java:251)
at org.testng.remote.RemoteTestNG.main(RemoteTestNG.java:77)
Caused by: java.lang.NullPointerException
at java.util.zip.DeflaterOutputStream.<init>(Unknown Source)
at java.util.zip.DeflaterOutputStream.<init>(Unknown Source)
at java.util.zip.ZipOutputStream.<init>(Unknown Source)
at java.util.zip.ZipOutputStream.<init>(Unknown Source)
at org.apache.poi.openxml4j.opc.ZipPackage.saveImpl(ZipPackage.java:531)
... 36 more
]]>
    </failure>
  </testcase> <!-- testMethod -->
  <testcase name="testMethod2" time="80.892" classname="testng.testingonly">
    <failure type="org.apache.poi.openxml4j.exceptions.OpenXML4JRuntimeException" message="Fail to save: an error occurs while saving the package : null">
      <![CDATA[org.apache.poi.openxml4j.exceptions.OpenXML4JRuntimeException: Fail to save: an error occurs while saving the package : null
at org.apache.poi.openxml4j.opc.ZipPackage.saveImpl(ZipPackage.java:602)
at org.apache.poi.openxml4j.opc.OPCPackage.save(OPCPackage.java:1557)
at org.apache.poi.POIXMLDocument.write(POIXMLDocument.java:248)
at configuration.excel.writeCellData(excel.java:174)
at testng.testingonly.writeToExcel(testingonly.java:1042)
at testng.testingonly.thirdPage(testingonly.java:1002)
at testng.testingonly.doWork(testingonly.java:404)
at testng.testingonly.testMethod2(testingonly.java:307)
at sun.reflect.NativeMethodAccessorImpl.invoke0(Native Method)
at sun.reflect.NativeMethodAccessorImpl.invoke(Unknown Source)
at sun.reflect.DelegatingMethodAccessorImpl.invoke(Unknown Source)
at java.lang.reflect.Method.invoke(Unknown Source)
at org.testng.internal.MethodInvocationHelper.invokeMethod(MethodInvocationHelper.java:133)
at org.testng.internal.TestInvoker.invokeMethod(TestInvoker.java:584)
at org.testng.internal.TestInvoker.invokeTestMethod(TestInvoker.java:172)
at org.testng.internal.MethodRunner.runInSequence(MethodRunner.java:46)
at org.testng.internal.TestInvoker$MethodInvocationAgent.invoke(TestInvoker.java:804)
at org.testng.internal.TestInvoker.invokeTestMethods(TestInvoker.java:145)
at org.testng.internal.TestMethodWorker.invokeTestMethods(TestMethodWorker.java:146)
at org.testng.internal.TestMethodWorker.run(TestMethodWorker.java:128)
at java.util.ArrayList.forEach(Unknown Source)
at org.testng.TestRunner.privateRun(TestRunner.java:770)
at org.testng.TestRunner.run(TestRunner.java:591)
at org.testng.SuiteRunner.runTest(SuiteRunner.java:402)
at org.testng.SuiteRunner.runSequentially(SuiteRunner.java:396)
at org.testng.SuiteRunner.privateRun(SuiteRunner.java:355)
at org.testng.SuiteRunner.run(SuiteRunner.java:304)
at org.testng.SuiteRunnerWorker.runSuite(SuiteRunnerWorker.java:53)
at org.testng.SuiteRunnerWorker.run(SuiteRunnerWorker.java:96)
at org.testng.TestNG.runSuitesSequentially(TestNG.java:1180)
at org.testng.TestNG.runSuitesLocally(TestNG.java:1102)
at org.testng.TestNG.runSuites(TestNG.java:1032)
at org.testng.TestNG.run(TestNG.java:1000)
at org.testng.remote.AbstractRemoteTestNG.run(AbstractRemoteTestNG.java:115)
at org.testng.remote.RemoteTestNG.initAndRun(RemoteTestNG.java:251)
at org.testng.remote.RemoteTestNG.main(RemoteTestNG.java:77)
Caused by: java.lang.NullPointerException
at java.util.zip.DeflaterOutputStream.<init>(Unknown Source)
at java.util.zip.DeflaterOutputStream.<init>(Unknown Source)
at java.util.zip.ZipOutputStream.<init>(Unknown Source)
at java.util.zip.ZipOutputStream.<init>(Unknown Source)
at org.apache.poi.openxml4j.opc.ZipPackage.saveImpl(ZipPackage.java:531)
... 35 more
]]>
    </failure>
  </testcase> <!-- testMethod2 -->
  <testcase name="testMethod3" time="83.065" classname="testng.testingonly">
    <failure type="org.apache.poi.openxml4j.exceptions.OpenXML4JRuntimeException" message="Fail to save: an error occurs while saving the package : null">
      <![CDATA[org.apache.poi.openxml4j.exceptions.OpenXML4JRuntimeException: Fail to save: an error occurs while saving the package : null
at org.apache.poi.openxml4j.opc.ZipPackage.saveImpl(ZipPackage.java:602)
at org.apache.poi.openxml4j.opc.OPCPackage.save(OPCPackage.java:1557)
at org.apache.poi.POIXMLDocument.write(POIXMLDocument.java:248)
at configuration.excel.writeCellData(excel.java:174)
at testng.testingonly.writeToExcel(testingonly.java:1042)
at testng.testingonly.getRerateId(testingonly.java:1033)
at testng.testingonly.thirdPage(testingonly.java:928)
at testng.testingonly.doWork(testingonly.java:404)
at testng.testingonly.testMethod3(testingonly.java:331)
at sun.reflect.NativeMethodAccessorImpl.invoke0(Native Method)
at sun.reflect.NativeMethodAccessorImpl.invoke(Unknown Source)
at sun.reflect.DelegatingMethodAccessorImpl.invoke(Unknown Source)
at java.lang.reflect.Method.invoke(Unknown Source)
at org.testng.internal.MethodInvocationHelper.invokeMethod(MethodInvocationHelper.java:133)
at org.testng.internal.TestInvoker.invokeMethod(TestInvoker.java:584)
at org.testng.internal.TestInvoker.invokeTestMethod(TestInvoker.java:172)
at org.testng.internal.MethodRunner.runInSequence(MethodRunner.java:46)
at org.testng.internal.TestInvoker$MethodInvocationAgent.invoke(TestInvoker.java:804)
at org.testng.internal.TestInvoker.invokeTestMethods(TestInvoker.java:145)
at org.testng.internal.TestMethodWorker.invokeTestMethods(TestMethodWorker.java:146)
at org.testng.internal.TestMethodWorker.run(TestMethodWorker.java:128)
at java.util.ArrayList.forEach(Unknown Source)
at org.testng.TestRunner.privateRun(TestRunner.java:770)
at org.testng.TestRunner.run(TestRunner.java:591)
at org.testng.SuiteRunner.runTest(SuiteRunner.java:402)
at org.testng.SuiteRunner.runSequentially(SuiteRunner.java:396)
at org.testng.SuiteRunner.privateRun(SuiteRunner.java:355)
at org.testng.SuiteRunner.run(SuiteRunner.java:304)
at org.testng.SuiteRunnerWorker.runSuite(SuiteRunnerWorker.java:53)
at org.testng.SuiteRunnerWorker.run(SuiteRunnerWorker.java:96)
at org.testng.TestNG.runSuitesSequentially(TestNG.java:1180)
at org.testng.TestNG.runSuitesLocally(TestNG.java:1102)
at org.testng.TestNG.runSuites(TestNG.java:1032)
at org.testng.TestNG.run(TestNG.java:1000)
at org.testng.remote.AbstractRemoteTestNG.run(AbstractRemoteTestNG.java:115)
at org.testng.remote.RemoteTestNG.initAndRun(RemoteTestNG.java:251)
at org.testng.remote.RemoteTestNG.main(RemoteTestNG.java:77)
Caused by: java.lang.NullPointerException
at java.util.zip.DeflaterOutputStream.<init>(Unknown Source)
at java.util.zip.DeflaterOutputStream.<init>(Unknown Source)
at java.util.zip.ZipOutputStream.<init>(Unknown Source)
at java.util.zip.ZipOutputStream.<init>(Unknown Source)
at org.apache.poi.openxml4j.opc.ZipPackage.saveImpl(ZipPackage.java:531)
... 36 more
]]>
    </failure>
  </testcase> <!-- testMethod3 -->
</testsuite> <!-- Default test -->
